<?xml version="1.0"?>
<!-- ******************************************* -->
<!-- MASKOR EV3 BOBB3E URDF MODEL                -->
<!-- Marcel Stuettgen                            -->
<!-- stuettgen@fh-aachen.de                      -->
<!-- Dennis Miltz                                -->
<!-- dennis.miltz@alumni.fh-aachen.de            -->
<!-- Christoph Gollok                            -->
<!-- christoph.gollok@alumni.fh-aachen.de        -->
<!-- ******************************************* -->
<!-- FH Aachen University of Applied Sciences    -->
<!-- MASCOR Institute                            -->
<!-- ******************************************* -->


<robot name="maskor_ev3_bobb3e" xmlns:xacro="http://ros.org/wiki/xacro">

  <material name="white">
    <color rgba="1 1 1 1"/>
  </material>

  <material name="black">
    <color rgba="0 0 0 1"/>
  </material>


  <property name="M_PI" value="3.14159" />

  <property name="dummy_mass" value="0.1" />
  <property name="dummy_inertia" value="0.0001" />

  <property name="base_to_wheel_x" value="0.17" />
  <property name="base_to_wheel_y" value="0.125" />
  <property name="base_to_wheel_z" value="0.03" />

  <property name="wheel_radius" value="0.12" />
  <property name="wheel_thickness" value="0.05" />
  <property name="wheel_mass" value="0.2" />
  <property name="wheel_model_scale" value="1 1 1" />



  <!-- Null inertial element. This is needed to make the model work with
       Gazebo. -->
  <xacro:macro name="null_inertial">
    <inertial>
      <mass value="0.001"/>
      <inertia ixx="0.001" ixy="0" ixz="0" iyy="0.001" iyz="0" izz="0.001"/>
    </inertial>
  </xacro:macro>

  <!-- Inertia of a solid cuboid. Width is measured along the x axis, depth
       along the y axis, and height along the z axis. -->
  <xacro:macro name="solid_cuboid_inertial"
               params="width depth height mass *origin">
    <inertial>
      <xacro:insert_block name="origin"/>
      <mass value="${mass}"/>
      <inertia ixx="${mass * (depth * depth + height * height) / 12}"
               ixy="0" ixz="0"
               iyy="${mass * (width * width + height * height) / 12}"
               iyz="0"
               izz="${mass * (width * width + depth * depth) / 12}"/>
    </inertial>
  </xacro:macro>

  <!-- Inertia of a thick-walled cylindrical tube with open ends. Height is
       measured along the z axis, which is the tube's axis. inner_rad and
       outer_rad are the tube's inner and outer radii, respectively. -->
  <xacro:macro name="thick_walled_tube_inertial"
               params="inner_rad outer_rad height mass">
    <inertial>
      <mass value="${mass}"/>
      <inertia ixx="${(1 / 12) * mass * (3 * (inner_rad * inner_rad +
                    outer_rad * outer_rad) + height * height)}"
               ixy="0" ixz="0"
               iyy="${(1 / 12) * mass * (3 * (inner_rad * inner_rad +
                    outer_rad * outer_rad) + height * height)}"
               iyz="0"
               izz="${mass * (inner_rad * inner_rad +
                    outer_rad * outer_rad) / 2}"/>
    </inertial>
  </xacro:macro>






  <!-- ************** -->
  <!-- BASE FOOTPRINT -->
  <!-- ************** -->
  <link name="base_footprint">
  </link>


  <!-- ************** -->
  <!-- BASE LINK      -->
  <!-- ************** -->
  <link name="base_link">
    <visual>
      <geometry>
	<mesh filename="package://maskor_ev3_description/meshes/bobb3e_baseLink.dae" scale="1 1 1"/>
	<!--box size="0.005 0.005 0.005"/-->
      </geometry>
      <origin rpy="0 0 0" xyz="0 0 -0.04"/>
      <material name="black"/>
    </visual>

    <collision>
      <geometry>
	<box size="0.125 0.105 0.07"/>
      </geometry>
      <origin rpy="0 0 0" xyz="0.02 0 0.01"/>
    </collision>

    <inertial>
      <mass value="1.0"/>
      <inertia ixx="0.4" ixy="0.0" ixz="0.0" iyy="0.4" iyz="0.0" izz="0.2"/>
    </inertial>



  </link>


  <!-- ******************** -->
  <!-- LEFT FRONT WHEEL     -->
  <!-- ******************** -->
  <link name="left_front_wheel_link">
    <visual>
      <geometry>
	       <mesh filename="package://maskor_ev3_description/meshes/bobb3e_tire.dae" scale="1 1 1"/>
      </geometry>
      <material name="black"/>
      <origin rpy="0 0 0" xyz="0 0 0"/>
    </visual>

    <collision>
      <geometry>
	       <cylinder length="0.02" radius="0.015"/>
      </geometry>
      <origin rpy="1.570 1.570 0" xyz="0 0 0" />
    </collision>

    <inertial>
      <mass value="3.0"/>
      <inertia ixx="0.4" ixy="0.0" ixz="0.0" iyy="0.4" iyz="0.0" izz="0.2"/>
    </inertial>

  </link>

  <!-- ****************** -->
  <!-- RIGHT FRONT WHEEL  -->
  <!-- *****************  -->
  <link name="right_front_wheel_link">
    <visual>
      <geometry>
	       <mesh filename="package://maskor_ev3_description/meshes/bobb3e_tire.dae" scale="1 1 1"/>
      </geometry>
      <material name="black"/>
      <origin rpy="0 0 0" xyz="0 0 0"/>
    </visual>

    <collision>
      <geometry>
	       <cylinder length="0.02" radius="0.015"/>
      </geometry>
      <origin rpy="1.570 1.570 0" xyz="0 0 0" />
    </collision>

    <inertial>
      <mass value="3.0"/>
      <inertia ixx="0.4" ixy="0.0" ixz="0.0" iyy="0.4" iyz="0.0" izz="0.2"/>
    </inertial>

  </link>

  <!-- ******************** -->
  <!-- LEFT REAR  WHEEL     -->
  <!-- ******************** -->
  <link name="left_rear_wheel_link">
    <visual>
      <geometry>
	<mesh filename="package://maskor_ev3_description/meshes/bobb3e_tire.dae" scale="1 1 1"/>
      </geometry>
      <material name="black"/>
      <origin rpy="0 0 0" xyz="0 0 0"/>
    </visual>

    <collision>
      <geometry>
	<cylinder length="0.02" radius="0.015"/>
      </geometry>
      <origin rpy="1.570 1.570 0" xyz="0 0 0" />
    </collision>

    <inertial>
      <mass value="3.0"/>
      <inertia ixx="0.4" ixy="0.0" ixz="0.0" iyy="0.4" iyz="0.0" izz="0.2"/>
    </inertial>

  </link>

  <!-- ******************** -->
  <!-- RIGHT REAR WHEEL     -->
  <!-- ******************** -->
  <link name="right_rear_wheel_link">
    <visual>
      <geometry>
	<mesh filename="package://maskor_ev3_description/meshes/bobb3e_tire.dae" scale="1 1 1"/>
      </geometry>
      <material name="black"/>
      <origin rpy="0 0 0" xyz="0 0 0"/>
    </visual>

    <collision>
      <geometry>
	<cylinder length="0.02" radius="0.015"/>
      </geometry>
      <origin rpy="1.570 1.570 0" xyz="0 0 0" />
    </collision>

    <inertial>
      <mass value="3.0"/>
      <inertia ixx="0.4" ixy="0.0" ixz="0.0" iyy="0.4" iyz="0.0" izz="0.2"/>
    </inertial>

  </link>



  <!-- ************** -->
  <!-- COLOR SENSOR     -->
  <!-- ************** -->
  <link name="color_sensor_link">
    <visual>
      <geometry>
	<box size="0.001 0.001 0.001"/>
      </geometry>
      <origin rpy="0 1.5708 0" xyz="0 0 0"/>
      <material name="black"/>
    </visual>

    <collision>
      <geometry>
	<box size="0.025 0.025 0.045"/>
      </geometry>
     <origin rpy="0 1.5708 0" xyz="-0 0 0.01"/>
   </collision>
<!--1.5708-->
     <xacro:null_inertial/>

  </link>

  <!-- ************** -->
  <!-- GYRO SENSOR     -->
  <!-- ************** -->
  <link name="gyro_sensor_link">
    <visual>
      <geometry>
	<box size="0.002 0.002 0.004"/>
      </geometry>
      <origin rpy="0 0 0" xyz="0 0 0"/>
      <material name="black"/>
    </visual>

    <collision>
      <geometry>
	<box size="0.002 0.002 0.004"/>
      </geometry>
    </collision>

    <xacro:null_inertial/>

  </link>

  <!-- ***************  -->
  <!-- INFRARED SENSOR -->
  <!-- ***************  -->
  <link name="infrared_sensor_link">
    <visual>
      <geometry>
	<box size="0.01 0.01 0.01"/>
      </geometry>
      <origin rpy="0 0 0" xyz="0 0 0"/>
      <material name="black"/>
    </visual>

    <collision>
      <geometry>
	<box size="0.055 0.065 0.03"/>
      </geometry>
      <origin rpy="0 0 0" xyz="-0.01 0 0"/>
    </collision>

    <xacro:null_inertial/>
  </link>


 <!-- ************** -->
  <!-- FORK LIFT     -->
  <!-- ************** -->
  <link name="fork_lift_link">
    <visual>
      <geometry>
	<mesh filename="package://maskor_ev3_description/meshes/bobb3e_fork_lift.dae" scale="1 1 1"/>
	<!-- <box size="0.01 0.01 0.035"/> -->
      </geometry>
      <origin rpy="0 0 0" xyz="0.011 0 0"/>
      <material name="black"/>
    </visual>

    <collision>
      <geometry>
	<box size="0.01 0.089 0.064"/>
      </geometry>
      <origin rpy="0 0 0" xyz="0 0 0.01"/>
    </collision>

    <inertial>
      <mass value="0.1"/>
      <inertia ixx="0.4" ixy="0.0" ixz="0.0" iyy="0.4" iyz="0.0" izz="0.2"/>
    </inertial>

  </link>

  <!-- ***************  -->
  <!-- Fork              -->
  <!-- ***************  -->

  <link name="left_fork_link">
    <visual>
      <geometry>
	<box size="0.01 0.01 0.01"/>
      </geometry>
      <origin rpy="0 0 0" xyz="0 0 0"/>
      <material name="black"/>
    </visual>

    <collision>
      <geometry>
	<box size="0.073 0.016 0.01"/>
      </geometry>
      <origin rpy="0 0 0" xyz="0.035 0.02 -0.02"/>
    </collision>

    <xacro:null_inertial/>

  </link>

  <link name="right_fork_link">
    <visual>
      <geometry>
	<box size="0.01 0.01 0.01"/>
      </geometry>
      <origin rpy="0 0 0" xyz="0 0 0"/>
      <material name="black"/>
    </visual>

    <collision>
      <geometry>
	<box size="0.073 0.016 0.01"/>
      </geometry>
      <origin rpy="0 0 0" xyz="0.035 -0.02 -0.02"/>
    </collision>

    <xacro:null_inertial/>

  </link>


  <!-- ************** -->
  <!-- ARMS            -->
  <!-- ************** -->

  <link name="left_fork_arm_link">
    <visual>
      <geometry>
	<mesh filename="package://maskor_ev3_description/meshes/bobb3e_arm_left.dae" scale="1 1 1"/>
      </geometry>
      <origin rpy="0 0 0" xyz="0.07 0 0"/>
      <material name="black"/>
    </visual>

    <xacro:null_inertial/>
  </link>

  <link name="right_fork_arm_link">
    <visual>
      <geometry>
	<mesh filename="package://maskor_ev3_description/meshes/bobb3e_arm_left.dae" scale="1 1 1"/>
      </geometry>
      <origin rpy="3.14159 0 0" xyz="0.07 0 0"/>
      <material name="black"/>
    </visual>

    <xacro:null_inertial/>

  </link>


  <!-- ************** -->
  <!-- JOINTS         -->
  <!-- ************** -->
  <joint name="base_link_to_base_footprint" type="fixed">
    <parent link="base_footprint"/>
    <child link="base_link"/>
    <origin xyz="0 0 0.03"/>
  </joint>

  <joint name="base_link_to_left_front_wheel" type="continuous">
    <dynamics damping="0" friction="15" />
    <parent link="base_link"/>
    <child link="left_front_wheel_link"/>
    <origin xyz="0.078 0.065 -0.018"/>
    <axis xyz="0 1 0"/>
  </joint>

  <joint name="base_link_to_left_rear_wheel" type="continuous">
    <dynamics damping="0" friction="15" />
    <parent link="base_link"/>
    <child link="left_rear_wheel_link"/>
    <origin xyz="-0.0175 0.065 -0.018"/>
    <axis xyz="0 1 0"/>
  </joint>

  <joint name="base_link_to_right_front_wheel" type="continuous">
    <dynamics damping="0" friction="15" />
    <parent link="base_link"/>
    <child link="right_front_wheel_link"/>
    <origin xyz="0.078 -0.065 -0.018"/>
    <axis xyz="0 1 0"/>
  </joint>

  <joint name="base_link_to_right_rear_wheel" type="continuous">
    <dynamics damping="0" friction="15" />
    <parent link="base_link"/>
    <child link="right_rear_wheel_link"/>
    <origin xyz="-0.0175 -0.065 -0.018"/>
    <axis xyz="0 1 0"/>
  </joint>

  <joint name="base_link_to_color_sensor" type="fixed">
    <parent link="base_link"/>
    <child link="color_sensor_link"/>
    <origin xyz="0.1 -0.0 -0.01" rpy="0 1.5708 0"/>
  </joint>

  <joint name="base_link_to_fork_lift_link" type="prismatic">
    <parent link="base_link"/>
    <child link="fork_lift_link"/>
    <origin rpy="0 0 0" xyz="0.11 0 0.02"/>
    <axis xyz="0 0 1"/>
    <limit effort="50.0" lower="-0.025" upper="0.11" velocity="0.5"/>
  </joint>

  <joint name="base_link_to_right_fork_arm" type="revolute">
    <parent link="base_link"/>
    <child link="right_fork_arm_link"/>
    <axis xyz="0 1 0"/>
    <origin rpy="0 0 0" xyz="-0.01 -0.05 0.07"/>
    <limit effort="50.0" lower="-0.50" upper="0.50" velocity="0.5"/>
  </joint>

 <joint name="base_link_to_left_fork_arm" type="revolute">
    <parent link="base_link"/>
    <child link="left_fork_arm_link"/>
    <axis xyz="0 1 0"/>
    <origin rpy="0 0 0" xyz="-0.01 0.05 0.07"/>
    <limit effort="50.0" lower="-0.50" upper="0.50" velocity="0.5"/>
  </joint>

  <joint name="base_link_to_gyro_sensor" type="fixed">
    <parent link="base_link"/>
    <child link="gyro_sensor_link"/>
    <origin xyz="-0.03 -0.06 0.075"/>
  </joint>

  <joint name="base_link_to_infrared_sensor" type="fixed">
    <parent link="base_link"/>
    <child link="infrared_sensor_link"/>
    <origin rpy="0 0.5 0" xyz="0 0 0.15"/>
  </joint>

  <joint name="fork_link_to_left_fork" type="fixed">
    <parent link="fork_lift_link"/>
    <child link="left_fork_link"/>
    <origin xyz="0 0.015 0"/>
  </joint>

  <joint name="fork_link_to_right_fork" type="fixed">
    <parent link="fork_lift_link"/>
    <child link="right_fork_link"/>
    <origin xyz="0 -0.015 0"/>
  </joint>



  <!-- ************** -->
  <!-- EV3 Plugins    -->
  <!-- ************** -->

  <gazebo>
    
    <plugin name="maskor_ev3_bobb3e_arm_plugin" filename="libmaskor_ev3_bobb3e_arm_plugin.so">
      <robotNamespace></robotNamespace>
      <publishArmJointStates>true</publishArmJointStates>

      <leftForkJoint>base_link_to_left_fork_arm</leftForkJoint>
      <rightForkJoint>base_link_to_right_fork_arm</rightForkJoint>
      <forkLiftJoint>base_link_to_fork_lift_link</forkLiftJoint>

      <forkTorque>2.0</forkTorque>
      <commandTopic>cmd_vel</commandTopic>
      <updateRate>100.0</updateRate>
    </plugin>

    

    <plugin name="maskor_ev3_bobb3e_skid_plugin" filename="libmaskor_ev3_bobb3e_skid_plugin.so">
      <robotNamespace></robotNamespace>
      <broadcastTF>true</broadcastTF>
      <publishWheelJointStates>true</publishWheelJointStates>
      
      <leftFrontJoint>base_link_to_left_front_wheel</leftFrontJoint>
      <rightFrontJoint>base_link_to_right_front_wheel</rightFrontJoint>
      <leftRearJoint>base_link_to_left_rear_wheel</leftRearJoint>
      <rightRearJoint>base_link_to_right_rear_wheel</rightRearJoint>

      <wheelSeparation>0.13</wheelSeparation>
      <wheelDiameter>0.04</wheelDiameter>
      <torque>1.0</torque>

      <commandTopic>cmd_vel</commandTopic>
      <odometryTopic>bobb3e/odom</odometryTopic>
      <odometryFrame>odom</odometryFrame>
      <robotBaseFrame>base_footprint</robotBaseFrame>
      <updateRate>100.0</updateRate>
      <covariance_x>0.0001</covariance_x>      
      <covariance_y>0.0001</covariance_y>      
      <covariance_yaw>0.01</covariance_yaw>      
    </plugin>  

    
    <plugin name="maskor_ev3_gyro_sensor_plugin" filename="libmaskor_ev3_gyro_sensor_plugin.so">
      <robotNamespace></robotNamespace>
      <gyroSensorTopic>bobb3e/gyro_sensor</gyroSensorTopic>
      <gyroSensorFrame>gyro_sensor_link</gyroSensorFrame>
      <rate>20.0</rate>
    </plugin>    

  </gazebo>

  <!-- ************** -->
  <!-- CameraPlugin   -->
  <!-- ************** -->
<gazebo reference="color_sensor_link">
 <sensor type="camera" name="camera1">
   <update_rate>30.0</update_rate>
   <camera name="head">
     <horizontal_fov>1.3962634</horizontal_fov>
     <image>
       <width>40</width>
       <height>40</height>
       <format>R8G8B8</format>
     </image>
     <clip>
       <near>0.02</near>
       <far>300</far>
     </clip>
     <noise>
       <type>gaussian</type>
       <!-- Noise is sampled independently per pixel on each frame.
            That pixel's noise value is added to each of its color
            channels, which at that point lie in the range [0,1]. -->
       <mean>0.0</mean>
       <stddev>0.007</stddev>
     </noise>
   </camera>
   <plugin name="camera_controller" filename="libgazebo_ros_camera.so">
     <alwaysOn>true</alwaysOn>
     <updateRate>0.0</updateRate>
     <cameraName>bobb3e/camera1</cameraName>
     <imageTopicName>image_raw</imageTopicName>
     <cameraInfoTopicName>camera_info</cameraInfoTopicName>
     <frameName>color_sensor_link</frameName>
     <hackBaseline>0.07</hackBaseline>
     <distortionK1>0.0</distortionK1>
     <distortionK2>0.0</distortionK2>
     <distortionK3>0.0</distortionK3>
     <distortionT1>0.0</distortionT1>
     <distortionT2>0.0</distortionT2>
   </plugin>
 </sensor>
</gazebo>


<!-- ************** -->
<!-- Laser Plugin   -->
<!-- ************** -->
 <gazebo reference="infrared_sensor_link">
   <sensor type="ray" name="head_hokuyo_sensor">
     <pose>0 0 0 0 0 0</pose>
     <visualize>true</visualize>
     <update_rate>40</update_rate>
     <ray>
       <scan>
         <horizontal>
           <samples>720</samples>
           <resolution>1</resolution>
           <min_angle>-0.34</min_angle>
           <max_angle>0.34</max_angle>
         </horizontal>
       </scan>
       <range>
         <min>0.10</min>
         <max>30.0</max>
         <resolution>0.01</resolution>
       </range>
       <noise>
         <type>gaussian</type>
         <!-- Noise parameters based on published spec for Hokuyo laser
              achieving "+-30mm" accuracy at range < 10m.  A mean of 0.0m and
              stddev of 0.01m will put 99.7% of samples within 0.03m of the true
              reading. -->
         <mean>0.0</mean>
         <stddev>0.01</stddev>
       </noise>
     </ray>
     <plugin name="gazebo_ros_head_hokuyo_controller" filename="libgazebo_ros_laser.so">
       <topicName>bobb3e/scan</topicName>
       <frameName>infrared_sensor_link</frameName>
     </plugin>
   </sensor>
 </gazebo>

</robot>
